<?xml version="1.0" encoding="utf-8"?>
<robot name="ec612">
   <link name="world" />
   <joint name="world_joint" type="fixed">
      <origin xyz="0 0 0" rpy="0 0 0" />
      <parent link="world" />
      <child link="base_link" />
   </joint>
   <link name="base_link">
   <inertial>
      <origin xyz="-0.0009283 -9.3169E-06 0.05675" rpy="0 0 0" />
      <mass value="0.96661" />
      <inertia ixx="0.0024056" ixy="-4.4072E-08" ixz="-3.4836E-05" iyy="0.0022827" iyz="-2.2372E-07" izz="0.0035887" />
   </inertial>
   <visual>
      <origin xyz="0 0 0" rpy="0 0 0" />
      <geometry>
         <mesh filename="package://elite_description/meshes/ec612/base_link.STL" />
      </geometry>
      <material name="">
         <color rgba="0.79216 0.81961 0.93333 1" />
      </material>
   </visual>
   <collision>
      <origin xyz="0 0 0" rpy="0 0 0" />
      <geometry>
         <mesh filename="package://elite_description/meshes/ec612/base_link.STL" />
      </geometry>
   </collision>
   </link>
   <link name="link1">
   <inertial>
      <origin xyz="-3.9632E-06 0.010506 -0.0056292" rpy="0 0 0" />
      <mass value="3.5947" />
      <inertia ixx="0.01211" ixy="-1.906E-07" ixz="-5.9544E-08" iyy="0.011358" iyz="-0.0010317" izz="0.012021" />
   </inertial>
   <visual>
      <origin xyz="0 0 0" rpy="0 0 0" />
      <geometry>
         <mesh filename="package://elite_description/meshes/ec612/link1.STL" />
      </geometry>
      <material name="">
         <color rgba="1 1 1 1" />
      </material>
   </visual>
   <collision>
      <origin xyz="0 0 0" rpy="0 0 0" />
      <geometry>
         <mesh filename="package://elite_description/meshes/ec612/link1.STL" />
      </geometry>
   </collision>
   </link>
   <joint name="joint1" type="revolute">
      <origin xyz="0 0 0.185" rpy="0 0 0" />
      <parent link="base_link" />
      <child link="link1" />
      <axis xyz="0 0 1" />
      <limit lower="-6.2832" upper="6.2832" effort="200" velocity="2.0944" />
   </joint>
   <link name="link2">
   <inertial>
      <origin xyz="0.2558 8.685E-07 0.18308" rpy="0 0 0" />
      <mass value="10.706" />
      <inertia ixx="0.024512" ixy="2.4186E-07" ixz="-0.00065236" iyy="0.11916" iyz="3.9378E-07" izz="0.11941" />
   </inertial>
   <visual>
      <origin xyz="0 0 0" rpy="0 0 0" />
      <geometry>
         <mesh filename="package://elite_description/meshes/ec612/link2.STL" />
      </geometry>
      <material name="">
         <color rgba="1 1 1 1" />
      </material>
   </visual>
   <collision>
      <origin xyz="0 0 0" rpy="0 0 0" />
      <geometry>
         <mesh filename="package://elite_description/meshes/ec612/link2.STL" />
      </geometry>
   </collision>
   </link>
   <joint name="joint2" type="revolute">
      <origin xyz="0 0 0" rpy="-1.5708 0 0" />
      <parent link="link1" />
      <child link="link2" />
      <axis xyz="0 0 1" />
      <limit lower="-6.2832" upper="6.2832" effort="200" velocity="2.0944" />
   </joint>
   <link name="link3">
   <inertial>
      <origin xyz="0.28329 -7.9581E-06 0.060967" rpy="0 0 0" />
      <mass value="4.5456" />
      <inertia ixx="0.0049702" ixy="-1.4106E-07" ixz="0.00018593" iyy="0.050299" iyz="-2.6283E-07" izz="0.0503" />
   </inertial>
   <visual>
      <origin xyz="0 0 0" rpy="0 0 0" />
      <geometry>
         <mesh filename="package://elite_description/meshes/ec612/link3.STL" />
      </geometry>
      <material name="">
         <color rgba="1 1 1 1" />
      </material>
   </visual>
   <collision>
      <origin xyz="0 0 0" rpy="0 0 0" />
      <geometry>
         <mesh filename="package://elite_description/meshes/ec612/link3.STL" />
      </geometry>
   </collision>
   </link>
   <joint name="joint3" type="revolute">
      <origin xyz="0.615 0 0" rpy="0 0 0" />
      <parent link="link2" />
      <child link="link3" />
      <axis xyz="0 0 1" />
      <limit lower="-2.7925" upper="2.7925" effort="150" velocity="2.618" />
   </joint>
   <link name="link4">
   <inertial>
      <origin xyz="0.000499517889352763 0.000875789216374712 0.168282791916811" rpy="0 0 0" />
      <mass value="0.843449158786285" />
      <inertia ixx="0.000924074695306208" ixy="-1.6181467913015E-08" ixz="7.26551673486314E-10"
         iyy="0.000889444283147283" iyz="-0.000128958334773031" izz="0.00087341536640418" />
   </inertial>
   <visual>
      <origin xyz="0 0 0" rpy="0 0 0" />
      <geometry>
         <mesh filename="package://elite_description/meshes/ec612/link4.STL" />
      </geometry>
      <material name="">
         <color rgba="1 1 1 1" />
      </material>
   </visual>
   <collision>
      <origin xyz="0 0 0" rpy="0 0 0" />
      <geometry>
         <mesh filename="package://elite_description/meshes/ec612/link4.STL" />
      </geometry>
   </collision>
   </link>
   <joint name="joint4" type="revolute">
      <origin xyz="0.572 0 0" rpy="0 0 0" />
      <parent link="link3" />
      <child link="link4" />
      <axis xyz="0 0 1" />
      <limit lower="-6.2832" upper="6.2832" effort="35" velocity="3.6652" />
   </joint>
   <link name="link5">
   <inertial>
      <origin xyz="0.000499517889352097 0.000875839859510064 0.110782741273677" rpy="0 0 0" />
      <mass value="0.843449158786269" />
      <inertia ixx="0.000924074695306195" ixy="-1.6181467914913E-08" ixz="7.26551670563271E-10"
         iyy="0.000889444283147262" iyz="-0.000128958334773028" izz="0.00087341536640416" />
   </inertial>
   <visual>
      <origin xyz="0 0 0" rpy="0 0 0" />
      <geometry>
         <mesh filename="package://elite_description/meshes/ec612/link5.STL" />
      </geometry>
      <material name="">
         <color rgba="1 1 1 1" />
      </material>
   </visual>
   <collision>
      <origin xyz="0 0 0" rpy="0 0 0" />
      <geometry>
         <mesh filename="package://elite_description/meshes/ec612/link5.STL" />
      </geometry>
   </collision>
   </link>
   <joint name="joint5" type="revolute">
      <origin xyz="0 0 0.174" rpy="-1.5708 0 0" />
      <parent link="link4" />
      <child link="link5" />
      <axis xyz="0 0 1" />
      <limit lower="-6.2832" upper="6.2832" effort="30" velocity="3.6652" />
   </joint>
   <link name="link6">
   <inertial>
      <origin xyz="0.00050459 -0.00047999 -0.021345" rpy="0 0 0" />
      <mass value="0.20756" />
      <inertia ixx="0.00010768" ixy="-1.152E-09" ixz="-4.7861E-09" iyy="0.00011933" iyz="-8.1484E-08"
         izz="0.00017733" />
   </inertial>
   <visual>
      <origin xyz="0 0 0" rpy="0 0 0" />
      <geometry>
         <mesh filename="package://elite_description/meshes/ec612/link6.STL" />
      </geometry>
      <material name="">
         <color rgba="0.49804 0.49804 0.49804 1" />
      </material>
   </visual>
   <collision>
      <origin xyz="0 0 0" rpy="0 0 0" />
      <geometry>
         <mesh filename="package://elite_description/meshes/ec612/link6.STL" />
      </geometry>
   </collision>
   </link>
   <joint name="joint6" type="revolute">
      <origin xyz="0 0.103 0.116" rpy="-1.5708 0 0" />
      <parent link="link5" />
      <child link="link6" />
      <axis xyz="0 0 1" />
      <limit lower="-6.2832" upper="6.2832" effort="25" velocity="3.6652" />
   </joint>
   <link name="flan" />
   <joint name="flan_joint" type="fixed">
      <origin xyz="0 0 0" rpy="0 0 0" />
      <parent link="link6" />
      <child link="flan" />
   </joint>
   <transmission name="trans_joint1">
      <type>transmission_interface/SimpleTransmission</type>
      <joint name="joint1">
         <hardwareInterface>hardware_interface/PositionJointInterface</hardwareInterface>
      </joint>
      <actuator name="joint1_motor">
         <mechanicalReduction>1</mechanicalReduction>
      </actuator>
   </transmission>
   <transmission name="trans_joint2">
      <type>transmission_interface/SimpleTransmission</type>
      <joint name="joint2">
         <hardwareInterface>hardware_interface/PositionJointInterface</hardwareInterface>
      </joint>
      <actuator name="joint2_motor">
         <mechanicalReduction>1</mechanicalReduction>
      </actuator>
   </transmission>
   <transmission name="trans_joint3">
      <type>transmission_interface/SimpleTransmission</type>
      <joint name="joint3">
         <hardwareInterface>hardware_interface/PositionJointInterface</hardwareInterface>
      </joint>
      <actuator name="joint3_motor">
         <mechanicalReduction>1</mechanicalReduction>
      </actuator>
   </transmission>
   <transmission name="trans_joint4">
      <type>transmission_interface/SimpleTransmission</type>
      <joint name="joint4">
         <hardwareInterface>hardware_interface/PositionJointInterface</hardwareInterface>
      </joint>
      <actuator name="joint4_motor">
         <mechanicalReduction>1</mechanicalReduction>
      </actuator>
   </transmission>
   <transmission name="trans_joint5">
      <type>transmission_interface/SimpleTransmission</type>
      <joint name="joint5">
         <hardwareInterface>hardware_interface/PositionJointInterface</hardwareInterface>
      </joint>
      <actuator name="joint5_motor">
         <mechanicalReduction>1</mechanicalReduction>
      </actuator>
   </transmission>
   <transmission name="trans_joint6">
      <type>transmission_interface/SimpleTransmission</type>
      <joint name="joint6">
         <hardwareInterface>hardware_interface/PositionJointInterface</hardwareInterface>
      </joint>
      <actuator name="joint6_motor">
         <mechanicalReduction>1</mechanicalReduction>
      </actuator>
   </transmission>
   <gazebo>
      <plugin name="gazebo_ros_control" filename="libgazebo_ros_control.so">
         <robotNamespace>/</robotNamespace>
      </plugin>
   </gazebo>
</robot>